Workbook
Name ACTION: #REF!
Name ACTION: #REF!

Sheet Cover
B2: TEST REPORT DOCUMENT
A4: Project Name | B4: FoodResQ - Food Rescue and Donation Platform | E4: Creator | F4: FoodResQ QA Team
A5: Project Code | B5: SP26SE088 | E5: Issue Date | F5: 46249
A6: Document Code | B6: =B5&"_v1.0" -> SP26SE088_v1.0 | E6: Version | F6: 1
A9: Record of change
A10: Effective Date | B10: Version | C10: Change Item | D10: *A,D,M | E10: Change description | F10: Reference
A11: 46249 | B11: 1 | C11: Test case | D11: M | E11: Adapt test case list for FoodResQ project | F11: v1.0
A12: 46249 | B12: 1 | C12: Test Statistics | D12: M | E12: Adapt test statistics for FoodResQ project | F12: v1.0
A13: 46249 | B13: 1 | C13: Module test sheets | D13: M | E13: Replace sample LMS modules with FoodResQ functional flows | F13: v1.0
A14: 46249 | B14: 1 | C14: Environment | D14: M | E14: Update environment for NestJS, Next.js, React Native, PostgreSQL/PostGIS, Redis, and Socket.IO | F14: v1.0
A15: 46249 | B15: 1 | C15: Traceability | D15: A | E15: Add reservation, delivery, bulk run, trust, and notification coverage | F15: v1.0
A16: 46249 | B16: 1 | C16: Final review | D16: M | E16: Review formulas and exported workbook layout | F16: v1.0

Sheet Test Cases
D1: TEST CASE LIST
B3: Project Name | D3: FoodResQ - Food Rescue and Donation Platform
B4: Project Code | D4: SP26SE088
B5: Test Environment Setup Description | D5: 1. Backend: NestJS API Server 2. Database: PostgreSQL + PostGIS 3. Frontend: Next.js web portal and React Native mobile app 4. Cache/Queue: Redis, BullMQ 5. Realtime: Socket.IO 6. File storage: S3/Cloudinary-compatible object storage 7. Browser: Chrome, Edge
B8: No | C8: Function Name | D8: Sheet Name | E8: Description | F8: Pre-Condition
B9: 1 | C9: Login with valid receiver account | D9: =HYPERLINK("#'Login'!A1","Login") -> Login | E9: User is authenticated and redirected to the receiver home screen. | F9: Receiver account exists and is active
B10: 2 | C10: Login with invalid password | E10: System rejects login and displays an invalid credential message. | F10: User account exists
B11: 3 | C11: Login with banned account | E11: System blocks login and shows account status message. | F11: Account status is banned
B12: 4 | C12: Refresh access token | E12: Client refreshes token and continues the request without forcing logout. | F12: Refresh token is valid
B13: 5 | C13: Reject expired refresh token | E13: System clears session and redirects user to sign in. | F13: Refresh token is expired or revoked
B14: 6 | C14: Role guard blocks unauthorized route | E14: API returns forbidden response and no provider data is exposed. | F14: Receiver account is active
B15: 7 | C15: Register receiver with valid information and selfie | D15: =HYPERLINK("#'Register eKYC'!A1","Register eKYC") -> Register eKYC | E15: Receiver account is created and face enrollment status is completed. | F15: Email and phone are not registered
B16: 8 | C16: Register receiver without selfie | E16: System rejects registration and asks for face enrollment. | F16: Email and phone are not registered
B17: 9 | C17: Register provider with business profile | E17: Provider profile is created and awaits verification when required. | F17: Provider email is not registered
B18: 10 | C18: Register volunteer shipper with location permission | E18: Volunteer profile is created with availability disabled by default. | F18: Volunteer email is not registered
B19: 11 | C19: Reject duplicate email | E19: System displays duplicate email validation error. | F19: Email already exists
B20: 12 | C20: Reject weak password | E20: System displays password policy validation error. | F20: User has not registered
B21: 13 | C21: Social-login account gated by face enrollment | E21: Face enrollment gate blocks reservation until selfie is enrolled. | F21: Social-login account exists without face enrollment
B22: 14 | C22: Validate required address for delivery receiver | E22: System asks for a complete address and location. | F22: Receiver account registration is in progress
B23: 15 | C23: Logout successfully | D23: =HYPERLINK("#'Logout'!A1","Logout") -> Logout | E23: Access token is removed, socket disconnects, and user returns to sign-in screen. | F23: User is signed in
B24: 16 | C24: Request password reset for registered email | D24: =HYPERLINK("#'Password'!A1","Password") -> Password | E24: System sends reset/OTP flow and displays confirmation. | F24: User email exists
B25: 17 | C25: Reset password with valid OTP | E25: Password is updated and old credentials no longer work. | F25: User has a valid OTP
B26: 18 | C26: View current user profile | D26: =HYPERLINK("#'Profile Trust'!A1","Profile Trust") -> Profile Trust | E26: User information, role, trust score, and verification state are displayed. | F26: User is signed in
B27: 19 | C27: Update receiver delivery address | E27: Updated address and coordinates are saved successfully. | F27: Receiver is signed in
B28: 20 | C28: Update provider business information | E28: Provider profile displays updated business information. | F28: Provider account exists
B29: 21 | C29: Volunteer toggles availability | E29: Volunteer availability is updated and visible to delivery assignment service. | F29: Volunteer is verified
B30: 22 | C30: Restricted user daily reservation limit | E30: System blocks reservation according to restricted daily limit. | F30: User trust score is at or below restriction threshold
B31: 23 | C31: Banned user token revocation | E31: All refresh tokens are revoked and protected API access is denied. | F31: User status is banned
B32: 24 | C32: View trust score history | E32: Trust score history displays reason, score change, and timestamp. | F32: User has trust score history records
B33: 25 | C33: Apply no-show trust penalty | E33: Reservation becomes no_show, stock is restored, and receiver trust score decreases by 20 points. | F33: Receiver has a confirmed pickup reservation
B34: 26 | C34: Warn and apply late cancellation penalty | E34: System shows late-cancel warning, cancels reservation, restores stock, and reduces trust by 10 points. | F34: Reservation is inside late cancellation window
B35: 27 | C35: Apply food safety violation penalty | E35: Trust score decreases by 50 points and account restriction/ban threshold is applied if reached. | F35: Food safety violation evidence exists
B36: 28 | C36: Admin reviews pending provider KYC | D36: =HYPERLINK("#'Admin Controls'!A1","Admin Controls") -> Admin Controls | E36: Admin can view all submitted verification evidence and provider profile details. | F36: New provider account is pending verification
B37: 29 | C37: Admin approves provider profile | E37: Provider status becomes active and provider can create food listings. | F37: Provider KYC information is valid
B38: 30 | C38: Admin rejects incomplete provider profile | E38: Provider status is rejected and provider receives notification to correct missing information. | F38: Provider KYC information is incomplete or invalid
B39: 31 | C39: Admin views and filters user list | E39: User list filters correctly and selected user detail displays role, status, and trust score. | F39: Users exist across multiple roles
B40: 32 | C40: Admin bans user and revokes tokens | E40: User status becomes banned and all refresh tokens are revoked. | F40: User account exists and is eligible for moderation
B41: 33 | C41: Admin monitors delivery status | E41: Admin sees current delivery status, assigned shipper, and lifecycle progress. | F41: Delivery exists in assigned or in-progress status
B42: 34 | C42: Admin monitors bulk run progress | E42: Admin sees bulk run status, requested quantity, served quantity, and distribution progress. | F42: Bulk run exists with at least one distribution stop
B43: 35 | C43: Admin processes violation report | E43: Report status updates and related user/listing/trust action is applied according to admin decision. | F43: Violation report exists
...

Sheet Test Statistics
B1: TEST STATISTICS
B3: Project Name | C3: FoodResQ - Food Rescue and Donation Platform | E3: Creator | G3: FoodResQ QA Team
B4: Project Code | C4: SP26SE088 | E4: Reviewer/Approver | G4: Capstone Supervisor
B5: Document Code | C5: =C4&"_Test Report_v1.0" -> SP26SE088_Test Report_v1.0 | E5: Issue Date | G5: 46249
B6: Notes
B10: No | C10: Module code | D10: Passed | E10: Failed | F10: Pending | G10: N/A | H10: Number of test cases
B11: 1 | C11: =Login!B2 -> Login | D11: =Login!B6 -> 6 | E11: =Login!C6 -> 0 | F11: =Login!D6 -> 0 | G11: =Login!E6 -> 0 | H11: =Login!B4 -> 6
B12: 2 | C12: ='Register eKYC'!B2 -> Register eKYC | D12: ='Register eKYC'!B6 -> 8 | E12: ='Register eKYC'!C6 -> 0 | F12: ='Register eKYC'!D6 -> 0 | G12: ='Register eKYC'!E6 -> 0 | H12: ='Register eKYC'!B4 -> 8
B13: 3 | C13: =Logout!B2 -> Logout | D13: =Logout!B6 -> 1 | E13: =Logout!C6 -> 0 | F13: =Logout!D6 -> 0 | G13: =Logout!E6 -> 0 | H13: =Logout!B4 -> 1
B14: 4 | C14: =Password!B2 -> Password | D14: =Password!B6 -> 2 | E14: =Password!C6 -> 0 | F14: =Password!D6 -> 0 | G14: =Password!E6 -> 0 | H14: =Password!B4 -> 2
B15: 5 | C15: ='Profile Trust'!B2 -> Profile Trust | D15: ='Profile Trust'!B6 -> 10 | E15: ='Profile Trust'!C6 -> 0 | F15: ='Profile Trust'!D6 -> 0 | G15: ='Profile Trust'!E6 -> 0 | H15: ='Profile Trust'!B4 -> 10
B16: 6 | C16: ='Admin Controls'!B2 -> Admin Controls | D16: ='Admin Controls'!B6 -> 8 | E16: ='Admin Controls'!C6 -> 0 | F16: ='Admin Controls'!D6 -> 0 | G16: ='Admin Controls'!E6 -> 0 | H16: ='Admin Controls'!B4 -> 8
B17: 7 | C17: ='Food Listings'!B2 -> Food Listings | D17: ='Food Listings'!B6 -> 14 | E17: ='Food Listings'!C6 -> 0 | F17: ='Food Listings'!D6 -> 0 | G17: ='Food Listings'!E6 -> 0 | H17: ='Food Listings'!B4 -> 14
B18: 8 | C18: ='Reservations QR'!B2 -> Reservations QR | D18: ='Reservations QR'!B6 -> 7 | E18: ='Reservations QR'!C6 -> 0 | F18: ='Reservations QR'!D6 -> 0 | G18: ='Reservations QR'!E6 -> 0 | H18: ='Reservations QR'!B4 -> 7
B19: 9 | C19: ='Delivery Shipper'!B2 -> Delivery Shipper | D19: ='Delivery Shipper'!B6 -> 14 | E19: ='Delivery Shipper'!C6 -> 0 | F19: ='Delivery Shipper'!D6 -> 0 | G19: ='Delivery Shipper'!E6 -> 0 | H19: ='Delivery Shipper'!B4 -> 14
B20: 10 | C20: ='Campaign Kitchen Ops'!B2 -> Campaign Kitchen Ops | D20: ='Campaign Kitchen Ops'!B6 -> 28 | E20: ='Campaign Kitchen Ops'!C6 -> 0 | F20: ='Campaign Kitchen Ops'!D6 -> 0 | G20: ='Campaign Kitchen Ops'!E6 -> 0 | H20: ='Campaign Kitchen Ops'!B4 -> 28
B21: 11 | C21: ='Bulk Notifications'!B2 -> Bulk Notifications | D21: ='Bulk Notifications'!B6 -> 6 | E21: ='Bulk Notifications'!C6 -> 0 | F21: ='Bulk Notifications'!D6 -> 0 | G21: ='Bulk Notifications'!E6 -> 0 | H21: ='Bulk Notifications'!B4 -> 6
C23: Sub total | D23: =SUM(D11:D21) -> 104 | E23: =SUM(E11:E21) -> 0 | F23: =SUM(F11:F21) -> 0 | G23: =SUM(G11:G21) -> 0 | H23: =SUM(H11:H21) -> 104
C25: Test coverage | E25: 100 | F25: %
C26: Test successful coverage | E26: 100 | F26: %

Sheet Delivery Shipper
A2: Feature | B2: Delivery Shipper | R2: Passed
A3: Test requirement | B3: Delivery assignment, offers, live tracking, status lifecycle, and proof of handoff | R3: Failed
A4: Number of TCs | B4: 14 | R4: Pending
A5: Testing Round | B5: Passed | C5: Failed | D5: Pending | E5: N/A | R5: N/A
A6: Round 1 | B6: =COUNTIF($F$12:$F$1005,B$5) -> 14 | C6: =COUNTIF($F$12:$F$1005,C$5) -> 0 | D6: =COUNTIF($F$12:$F$1005,D$5) -> 0 | E6: =COUNTIF($F$12:$F$1005,E$5) -> 0
A7: Round 2 | B7: =COUNTIF($I$12:$I$1005,B$5) -> 14 | C7: =COUNTIF($I$12:$I$1005,C$5) -> 0 | D7: =COUNTIF($I$12:$I$1005,D$5) -> 0 | E7: =COUNTIF($I$12:$I$1005,E$5) -> 0
A8: Round 3 | B8: =COUNTIF($L$12:$L$1005,B$5) -> 14 | C8: =COUNTIF($L$12:$L$1005,C$5) -> 0 | D8: =COUNTIF($L$12:$L$1005,D$5) -> 0 | E8: =COUNTIF($L$12:$L$1005,E$5) -> 0
A10: Test Case ID | B10: Test Case Description | C10: Test Case Procedure | D10: Expected Results | E10: Pre-conditions | F10: Round 1 | G10: Test date | H10: Tester | I10: Round 2 | J10: Test date | K10: Tester | L10: Round 3 | M10: Test date | N10: Tester | O10: Note
A11: Delivery reservation
A12: TC57 | B12: Create delivery reservation | C12: 1. Open active listing 2. Select delivery option 3. Confirm receiver address 4. Reserve listing | D12: Delivery record is created with pending assignment status. | E12: Receiver has address and location | F12: Passed | G12: 46235 | H12: QA Team | I12: Passed | J12: 46242 | K12: QA Team | L12: Passed | M12: 46249 | N12: QA Team
A13: Shipper assignment and offers
A14: TC58 | B14: Broadcast delivery offer to nearest shippers | C14: 1. Create delivery reservation 2. Run assignment service 3. Check shipper app | D14: Nearest available verified shippers receive delivery offer. | E14: Verified available shippers exist nearby | F14: Passed | G14: 46235 | H14: QA Team | I14: Passed | J14: 46242 | K14: QA Team | L14: Passed | M14: 46249 | N14: QA Team
A15: TC59 | B15: Shipper accepts offer | C15: 1. Open shipper offer popup 2. Click Accept | D15: Delivery is assigned to the accepting shipper and other offers are closed. | E15: Delivery offer is active | F15: Passed | G15: 46235 | H15: QA Team | I15: Passed | J15: 46242 | K15: QA Team | L15: Passed | M15: 46249 | N15: QA Team
A16: TC60 | B16: Second shipper cannot accept assigned delivery | C16: 1. Assign delivery to first shipper 2. Second shipper clicks Accept | D16: System rejects second acceptance and keeps original shipper assignment. | E16: Delivery is already assigned | F16: Passed | G16: 46235 | H16: QA Team | I16: Passed | J16: 46242 | K16: QA Team | L16: Passed | M16: 46249 | N16: QA Team
A17: TC61 | B17: Shipper rejects offer | C17: 1. Open shipper offer popup 2. Click Reject | D17: Offer status becomes rejected and delivery can be offered to another shipper. | E17: Delivery offer is active | F17: Passed | G17: 46235 | H17: QA Team | I17: Passed | J17: 46242 | K17: QA Team | L17: Passed | M17: 46249 | N17: QA Team
A18: TC62 | B18: Expire stale delivery offer | C18: 1. Create delivery offer 2. Wait past offer expiry 3. Run sweep job | D18: Expired offer is closed and next nearest shippers are selected. | E18: Offer expires after configured time | F18: Passed | G18: 46235 | H18: QA Team | I18: Passed | J18: 46242 | K18: QA Team | L18: Passed | M18: 46249 | N18: QA Team
A19: TC63 | B19: Assignment timeout cancels delivery reservation | C19: 1. Create delivery with no accepting shippers 2. Wait assignment timeout 3. Run sweep job | D19: Delivery fails, reservation is cancelled without penalty, and stock is restored. | E19: No shipper accepts offer | F19: Passed | G19: 46235 | H19: QA Team | I19: Passed | J19: 46242 | K19: QA Team | L19: Passed | M19: 46249 | N19: QA Team
A20: Delivery lifecycle and proof
A21: TC64 | B21: Update delivery lifecycle status | C21: 1. Accept delivery 2. Set heading_to_provider 3. Set qc_completed 4. Set in_transit | D21: Delivery status advances in the allowed order. | E21: Delivery is assigned | F21: Passed | G21: 46235 | H21: QA Team | I21: Passed | J21: 46242 | K21: QA Team | L21: Passed | M21: 46249 | N21: QA Team
A22: TC65 | B22: Upload QC photo | C22: 1. Open assigned delivery 2. Take QC photo at provider 3. Submit photo | D22: QC proof URL is saved and status can move to in_transit. | E22: Shipper reached provider | F22: Passed | G22: 46235 | H22: QA Team | I22: Passed | J22: 46242 | K22: QA Team | L22: Passed | M22: 46249 | N22: QA Team
A23: TC66 | B23: Receiver tracks live shipper location | C23: 1. Open delivery tracking screen 2. Send shipper GPS update | D23: Map updates with latest shipper location through socket event. | E23: Delivery is in progress | F23: Passed | G23: 46235 | H23: QA Team | I23: Passed | J23: 46242 | K23: QA Team | L23: Passed | M23: 46249 | N23: QA Team
A24: TC67 | B24: Complete delivery with receiver QR | C24: 1. Arrive at receiver 2. Scan receiver QR 3. Confirm handoff | D24: Delivery is delivered, reservation is completed, and points/trust are updated. | E24: Delivery is in_transit | F24: Passed | G24: 46235 | H24: QA Team | I24: Passed | J24: 46242 | K24: QA Team | L24: Passed | M24: 46249 | N24: QA Team
A25: TC68 | B25: Reject delivery completion without QR | C25: 1. Open delivery completion 2. Skip QR scan 3. Submit completion | D25: System blocks delivery completion until receiver QR is scanned. | E25: Delivery is in_transit | F25: Passed | G25: 46235 | H25: QA Team | I25: Passed | J25: 46242 | K25: QA Team | L25: Passed | M25: 46249 | N25: QA Team
A26: Delivery exceptions
A27: TC69 | B27: Auto-fail stalled delivery | C27: 1. Set delivery with no status update for stall window 2. Run stalled delivery cron | D27: Delivery is marked failed and related users are notified. | E27: Delivery is stalled beyond configured hours | F27: Passed | G27: 46235 | H27: QA Team | I27: Passed | J27: 46242 | K27: QA Team | L27: Passed | M27: 46249 | N27: QA Team
A28: TC70 | B28: Cancel delivery before pickup | C28: 1. Open assigned delivery 2. Cancel before food pickup 3. Confirm cancellation | D28: Delivery is cancelled, offers are recalled, and reservation stock is restored if applicable. | E28: Food has not been picked up | F28: Passed | G28: 46235 | H28: QA Team | I28: Passed | J28: 46242 | K28: QA Team | L28: Passed | M28: 46249 | N28: QA Team

Sheet Food Listings
A2: Feature | B2: Food Listings | R2: Passed
A3: Test requirement | B3: Create, search, update, publish, and cancel food listings with pickup windows | R3: Failed
A4: Number of TCs | B4: 14 | R4: Pending
A5: Testing Round | B5: Passed | C5: Failed | D5: Pending | E5: N/A | R5: N/A
A6: Round 1 | B6: =COUNTIF($F$12:$F$1005,B$5) -> 14 | C6: =COUNTIF($F$12:$F$1005,C$5) -> 0 | D6: =COUNTIF($F$12:$F$1005,D$5) -> 0 | E6: =COUNTIF($F$12:$F$1005,E$5) -> 0
A7: Round 2 | B7: =COUNTIF($I$12:$I$1005,B$5) -> 14 | C7: =COUNTIF($I$12:$I$1005,C$5) -> 0 | D7: =COUNTIF($I$12:$I$1005,D$5) -> 0 | E7: =COUNTIF($I$12:$I$1005,E$5) -> 0
A8: Round 3 | B8: =COUNTIF($L$12:$L$1005,B$5) -> 14 | C8: =COUNTIF($L$12:$L$1005,C$5) -> 0 | D8: =COUNTIF($L$12:$L$1005,D$5) -> 0 | E8: =COUNTIF($L$12:$L$1005,E$5) -> 0
A10: Test Case ID | B10: Test Case Description | C10: Test Case Procedure | D10: Expected Results | E10: Pre-conditions | F10: Round 1 | G10: Test date | H10: Tester | I10: Round 2 | J10: Test date | K10: Tester | L10: Round 3 | M10: Test date | N10: Tester | O10: Note
A11: Listing discovery
A12: TC36 | B12: View nearby active listings | C12: 1. Open home screen 2. Allow location 3. Load nearby listings | D12: Only active listings within configured radius are displayed. | E12: Location permission is granted | F12: Passed | G12: 46235 | H12: QA Team | I12: Passed | J12: 46242 | K12: QA Team | L12: Passed | M12: 46249 | N12: QA Team
A13: TC37 | B13: Search listings by keyword | C13: 1. Open search 2. Enter food keyword 3. Submit search | D13: Listings matching keyword are shown with current availability. | E13: Active listings exist | F13: Passed | G13: 46235 | H13: QA Team | I13: Passed | J13: 46242 | K13: QA Team | L13: Passed | M13: 46249 | N13: QA Team
A14: TC38 | B14: Filter listings by category | C14: 1. Open listing filters 2. Choose food category 3. Apply filter | D14: Only listings in selected category are displayed. | E14: Active listings exist | F14: Passed | G14: 46235 | H14: QA Team | I14: Passed | J14: 46242 | K14: QA Team | L14: Passed | M14: 46249 | N14: QA Team
A15: TC39 | B15: View listing details | C15: 1. Open a listing card 2. Read detail page | D15: Food title, quantity, pickup address, pickup window, storage and allergen notes are displayed. | E15: Listing is active | F15: Passed | G15: 46235 | H15: QA Team | I15: Passed | J15: 46242 | K15: QA Team | L15: Passed | M15: 46249 | N15: QA Team
A16: TC48 | B16: Soft deleted listing hidden from search | C16: 1. Mark listing as deleted 2. Open receiver search 3. Search same area | D16: Deleted listing does not appear in search results. | E16: Listing has deleted_at set | F16: Passed | G16: 46235 | H16: QA Team | I16: Passed | J16: 46242 | K16: QA Team | L16: Passed | M16: 46249 | N16: QA Team
A17: TC49 | B17: Map pin opens listing detail | C17: 1. Open map view 2. Tap listing marker 3. Open detail | D17: Selected marker opens the correct listing detail. | E17: Listings with pickup coordinates exist | F17: Passed | G17: 46235 | H17: QA Team | I17: Passed | J17: 46242 | K17: QA Team | L17: Passed | M17: 46249 | N17: QA Team
A18: Listing management
A19: TC40 | B19: Create listing with valid data | C19: 1. Sign in as provider 2. Open Create Listing 3. Enter valid food details and pickup location 4. Submit form | D19: Listing is created in draft or active status according to provider flow. | E19: Provider is signed in | F19: Passed | G19: 46235 | H19: QA Team | I19: Passed | J19: 46242 | K19: QA Team | L19: Passed | M19: 46249 | N19: QA Team
A20: TC42 | B20: Upload listing images | C20: 1. Open listing form 2. Select valid image files 3. Submit listing | D20: Images are uploaded and linked to the listing. | E20: Provider is signed in | F20: Passed | G20: 46235 | H20: QA Team | I20: Passed | J20: 46242 | K20: QA Team | L20: Passed | M20: 46249 | N20: QA Team
A21: TC43 | B21: Publish draft listing | C21: 1. Open provider listing list 2. Select draft listing 3. Click Publish | D21: Listing status becomes active and appears in receiver search. | E21: Provider owns a draft listing | F21: Passed | G21: 46235 | H21: QA Team | I21: Passed | J21: 46242 | K21: QA Team | L21: Passed | M21: 46249 | N21: QA Team
A22: TC44 | B22: Update active listing | C22: 1. Open provider listing detail 2. Edit description or pickup notes 3. Save changes | D22: Listing information is updated without changing reservations. | E22: Provider owns the listing | F22: Passed | G22: 46235 | H22: QA Team | I22: Passed | J22: 46242 | K22: QA Team | L22: Passed | M22: 46249 | N22: QA Team
A23: TC45 | B23: Cancel listing | C23: 1. Open provider listing detail 2. Click Cancel 3. Confirm action | D23: Listing is no longer available for new reservations. | E23: Provider owns an active listing | F23: Passed | G23: 46235 | H23: QA Team | I23: Passed | J23: 46242 | K23: QA Team | L23: Passed | M23: 46249 | N23: QA Team
A24: Listing reservation constraints
A25: TC41 | B25: Reject listing with invalid quantity | C25: 1. Open Create Listing 2. Enter quantity as zero 3. Submit form | D25: System displays quantity validation error. | E25: Provider is signed in | F25: Passed | G25: 46235 | H25: QA Team | I25: Passed | J25: 46242 | K25: QA Team | L25: Passed | M25: 46249 | N25: QA Team
A26: TC46 | B26: Reject expired pickup window | C26: 1. Open a listing with closed pickup window 2. Try to reserve | D26: Reservation action is disabled or API rejects the request. | E26: Pickup end time has passed | F26: Passed | G26: 46235 | H26: QA Team | I26: Passed | J26: 46242 | K26: QA Team | L26: Passed | M26: 46249 | N26: QA Team
A27: TC47 | B27: Respect max per reservation | C27: 1. Open listing detail 2. Enter quantity above max per reservation 3. Submit reservation | D27: System displays max quantity validation error. | E27: Listing has max per reservation configured | F27: Passed | G27: 46235 | H27: QA Team | I27: Passed | J27: 46242 | K27: QA Team | L27: Passed | M27: 46249 | N27: QA Team

Sheet Reservations QR
A2: Feature | B2: Reservations QR | R2: Passed
A3: Test requirement | B3: Reserve food, enforce limits, generate QR, cancel, and complete pickup | R3: Failed
A4: Number of TCs | B4: 7 | R4: Pending
A5: Testing Round | B5: Passed | C5: Failed | D5: Pending | E5: N/A | R5: N/A
A6: Round 1 | B6: =COUNTIF($F$12:$F$1005,B$5) -> 7 | C6: =COUNTIF($F$12:$F$1005,C$5) -> 0 | D6: =COUNTIF($F$12:$F$1005,D$5) -> 0 | E6: =COUNTIF($F$12:$F$1005,E$5) -> 0
A7: Round 2 | B7: =COUNTIF($I$12:$I$1005,B$5) -> 7 | C7: =COUNTIF($I$12:$I$1005,C$5) -> 0 | D7: =COUNTIF($I$12:$I$1005,D$5) -> 0 | E7: =COUNTIF($I$12:$I$1005,E$5) -> 0
A8: Round 3 | B8: =COUNTIF($L$12:$L$1005,B$5) -> 7 | C8: =COUNTIF($L$12:$L$1005,C$5) -> 0 | D8: =COUNTIF($L$12:$L$1005,D$5) -> 0 | E8: =COUNTIF($L$12:$L$1005,E$5) -> 0
A10: Test Case ID | B10: Test Case Description | C10: Test Case Procedure | D10: Expected Results | E10: Pre-conditions | F10: Round 1 | G10: Test date | H10: Tester | I10: Round 2 | J10: Test date | K10: Tester | L10: Round 3 | M10: Test date | N10: Tester | O10: Note
A11: Reservation creation
A12: TC50 | B12: Create pickup reservation | C12: 1. Open active listing 2. Choose valid quantity 3. Click Reserve | D12: Reservation is confirmed, stock decreases, and QR token is generated. | E12: Receiver is signed in and face enrolled | F12: Passed | G12: 46235 | H12: QA Team | I12: Passed | J12: 46242 | K12: QA Team | L12: Passed | M12: 46249 | N12: QA Team
A13: Reservation validation
A14: TC51 | B14: Reject reservation outside pickup window | C14: 1. Open listing before pickup start or after pickup end 2. Submit reservation | D14: API rejects reservation with pickup window message. | E14: Listing pickup window is not open | F14: Passed | G14: 46235 | H14: QA Team | I14: Passed | J14: 46242 | K14: QA Team | L14: Passed | M14: 46249 | N14: QA Team
A15: TC52 | B15: Reject reservation over daily limit | C15: 1. Create reservations until daily limit reached 2. Try another reservation | D15: System blocks request according to daily reservation limit. | E15: Receiver reached daily limit | F15: Passed | G15: 46235 | H15: QA Team | I15: Passed | J15: 46242 | K15: QA Team | L15: Passed | M15: 46249 | N15: QA Team
A16: TC53 | B16: Prevent oversell under concurrent reservations | C16: 1. Start two reservation requests for remaining one portion 2. Submit both requests | D16: Only one request succeeds and stock never becomes negative. | E16: Listing has one portion remaining | F16: Passed | G16: 46235 | H16: QA Team | I16: Passed | J16: 46242 | K16: QA Team | L16: Passed | M16: 46249 | N16: QA Team
A17: QR pickup confirmation
A18: TC54 | B18: Provider scans valid QR | C18: 1. Open provider scanner 2. Scan receiver QR 3. Confirm pickup | D18: Reservation status changes to picked_up or completed according to pickup flow. | E18: Reservation is confirmed and QR not expired | F18: Passed | G18: 46235 | H18: QA Team | I18: Passed | J18: 46242 | K18: QA Team | L18: Passed | M18: 46249 | N18: QA Team
A19: TC55 | B19: Reject expired QR | C19: 1. Open provider scanner 2. Scan expired QR token | D19: System rejects QR and reservation is not completed. | E19: QR expires after configured validity | F19: Passed | G19: 46235 | H19: QA Team | I19: Passed | J19: 46242 | K19: QA Team | L19: Passed | M19: 46249 | N19: QA Team
A20: Reservation cancellation
A21: TC56 | B21: Receiver cancels reservation before penalty window | C21: 1. Open reservation detail 2. Click Cancel 3. Confirm cancellation | D21: Reservation is cancelled, stock is restored, and no late penalty is applied. | E21: Reservation is confirmed | F21: Passed | G21: 46235 | H21: QA Team | I21: Passed | J21: 46242 | K21: QA Team | L21: Passed | M21: 46249 | N21: QA Team

Sheet Bulk Notifications
A2: Feature | B2: Bulk Notifications | R2: Passed
A3: Test requirement | B3: Bulk-run approval, stop serving, completion, and notification read states | R3: Failed
A4: Number of TCs | B4: 6 | R4: Pending
A5: Testing Round | B5: Passed | C5: Failed | D5: Pending | E5: N/A | R5: N/A
A6: Round 1 | B6: =COUNTIF($F$12:$F$1005,B$5) -> 6 | C6: =COUNTIF($F$12:$F$1005,C$5) -> 0 | D6: =COUNTIF($F$12:$F$1005,D$5) -> 0 | E6: =COUNTIF($F$12:$F$1005,E$5) -> 0
A7: Round 2 | B7: =COUNTIF($I$12:$I$1005,B$5) -> 6 | C7: =COUNTIF($I$12:$I$1005,C$5) -> 0 | D7: =COUNTIF($I$12:$I$1005,D$5) -> 0 | E7: =COUNTIF($I$12:$I$1005,E$5) -> 0
A8: Round 3 | B8: =COUNTIF($L$12:$L$1005,B$5) -> 6 | C8: =COUNTIF($L$12:$L$1005,C$5) -> 0 | D8: =COUNTIF($L$12:$L$1005,D$5) -> 0 | E8: =COUNTIF($L$12:$L$1005,E$5) -> 0
A10: Test Case ID | B10: Test Case Description | C10: Test Case Procedure | D10: Expected Results | E10: Pre-conditions | F10: Round 1 | G10: Test date | H10: Tester | I10: Round 2 | J10: Test date | K10: Tester | L10: Round 3 | M10: Test date | N10: Tester | O10: Note
A11: Bulk run
A12: TC99 | B12: Request bulk run with valid quantity | C12: 1. Sign in as verified shipper 2. Open eligible listing 3. Request bulk quantity of at least ten portions | D12: Bulk run request is created with requested status. | E12: Listing has enough remaining quantity | F12: Passed | G12: 46235 | H12: QA Team | I12: Passed | J12: 46242 | K12: QA Team | L12: Passed | M12: 46249 | N12: QA Team
A13: TC100 | B13: Reject bulk run below minimum quantity | C13: 1. Open bulk request 2. Enter quantity below minimum 3. Submit request | D13: System displays minimum quantity validation error. | E13: Verified shipper is signed in | F13: Passed | G13: 46235 | H13: QA Team | I13: Passed | J13: 46242 | K13: QA Team | L13: Passed | M13: 46249 | N13: QA Team
A14: TC101 | B14: Provider approves bulk run | C14: 1. Sign in as provider 2. Open bulk request 3. Click Approve | D14: Stock is decremented atomically and bulk run status becomes approved. | E14: Provider owns listing and stock is sufficient | F14: Passed | G14: 46235 | H14: QA Team | I14: Passed | J14: 46242 | K14: QA Team | L14: Passed | M14: 46249 | N14: QA Team
A15: TC102 | B15: Add and serve bulk distribution stop | C15: 1. Open picked-up bulk run 2. Add distribution stop with location 3. Log served portions | D15: Stop is saved and served quantity is added without exceeding total quantity. | E15: Bulk run has been picked up | F15: Passed | G15: 46235 | H15: QA Team | I15: Passed | J15: 46242 | K15: QA Team | L15: Passed | M15: 46249 | N15: QA Team
A16: TC103 | B16: Complete bulk run with leftover stock return | C16: 1. Open active bulk run 2. Enter served quantity less than total 3. Click Complete | D16: Bulk run is completed and leftover portions return to listing stock. | E16: Bulk run is active | F16: Passed | G16: 46235 | H16: QA Team | I16: Passed | J16: 46242 | K16: QA Team | L16: Passed | M16: 46249 | N16: QA Team
A17: Notification center
A18: TC104 | B18: Read notification and update unread count | C18: 1. Open notifications 2. Click unread notification 3. Return to list | D18: Notification is marked as read and unread count decreases. | E18: User has unread notifications | F18: Passed | G18: 46235 | H18: QA Team | I18: Passed | J18: 46242 | K18: QA Team | L18: Passed | M18: 46249 | N18: QA Team

Sheet Register eKYC
A2: Feature | B2: Register eKYC | R2: Passed
A3: Test requirement | B3: Create receiver, provider, and volunteer accounts with validation and face enrollment | R3: Failed
A4: Number of TCs | B4: 8 | R4: Pending
A5: Testing Round | B5: Passed | C5: Failed | D5: Pending | E5: N/A | R5: N/A
A6: Round 1 | B6: =COUNTIF($F$12:$F$1005,B$5) -> 8 | C6: =COUNTIF($F$12:$F$1005,C$5) -> 0 | D6: =COUNTIF($F$12:$F$1005,D$5) -> 0 | E6: =COUNTIF($F$12:$F$1005,E$5) -> 0
A7: Round 2 | B7: =COUNTIF($I$12:$I$1005,B$5) -> 8 | C7: =COUNTIF($I$12:$I$1005,C$5) -> 0 | D7: =COUNTIF($I$12:$I$1005,D$5) -> 0 | E7: =COUNTIF($I$12:$I$1005,E$5) -> 0
A8: Round 3 | B8: =COUNTIF($L$12:$L$1005,B$5) -> 8 | C8: =COUNTIF($L$12:$L$1005,C$5) -> 0 | D8: =COUNTIF($L$12:$L$1005,D$5) -> 0 | E8: =COUNTIF($L$12:$L$1005,E$5) -> 0
A10: Test Case ID | B10: Test Case Description | C10: Test Case Procedure | D10: Expected Results | E10: Pre-conditions | F10: Round 1 | G10: Test date | H10: Tester | I10: Round 2 | J10: Test date | K10: Tester | L10: Round 3 | M10: Test date | N10: Tester | O10: Note
A11: eKYC and face enrollment
A12: TC07 | B12: Register receiver with valid information and selfie | C12: 1. Open receiver registration 2. Enter required profile fields 3. Capture selfie 4. Submit form | D12: Receiver account is created and face enrollment status is completed. | E12: Email and phone are not registered | F12: Passed | G12: 46235 | H12: QA Team | I12: Passed | J12: 46242 | K12: QA Team | L12: Passed | M12: 46249 | N12: QA Team
A13: TC08 | B13: Register receiver without selfie | C13: 1. Open receiver registration 2. Enter valid profile fields 3. Skip selfie capture 4. Submit form | D13: System rejects registration and asks for face enrollment. | E13: Email and phone are not registered | F13: Passed | G13: 46235 | H13: QA Team | I13: Passed | J13: 46242 | K13: QA Team | L13: Passed | M13: 46249 | N13: QA Team
A14: TC13 | B14: Social-login account gated by face enrollment | C14: 1. Sign in with social account 2. Open dashboard 3. Try to reserve a listing before face enrollment | D14: Face enrollment gate blocks reservation until selfie is enrolled. | E14: Social-login account exists without face enrollment | F14: Passed | G14: 46235 | H14: QA Team | I14: Passed | J14: 46242 | K14: QA Team | L14: Passed | M14: 46249 | N14: QA Team
A15: Account registration
A16: TC09 | B16: Register provider with business profile | C16: 1. Open provider registration 2. Enter business name, address, contact, and tax information 3. Submit form | D16: Provider profile is created and awaits verification when required. | E16: Provider email is not registered | F16: Passed | G16: 46235 | H16: QA Team | I16: Passed | J16: 46242 | K16: QA Team | L16: Passed | M16: 46249 | N16: QA Team
A17: TC10 | B17: Register volunteer shipper with location permission | C17: 1. Open volunteer registration 2. Enter personal information 3. Grant location permission 4. Submit form | D17: Volunteer profile is created with availability disabled by default. | E17: Volunteer email is not registered | F17: Passed | G17: 46235 | H17: QA Team | I17: Passed | J17: 46242 | K17: QA Team | L17: Passed | M17: 46249 | N17: QA Team
A18: Registration validation
A19: TC11 | B19: Reject duplicate email | C19: 1. Open registration 2. Enter an email already used by another user 3. Submit form | D19: System displays duplicate email validation error. | E19: Email already exists | F19: Passed | G19: 46235 | H19: QA Team | I19: Passed | J19: 46242 | K19: QA Team | L19: Passed | M19: 46249 | N19: QA Team
A20: TC12 | B20: Reject weak password | C20: 1. Open registration 2. Enter valid profile fields 3. Enter weak password 4. Submit form | D20: System displays password policy validation error. | E20: User has not registered | F20: Passed | G20: 46235 | H20: QA Team | I20: Passed | J20: 46242 | K20: QA Team | L20: Passed | M20: 46249 | N20: QA Team
A21: TC14 | B21: Validate required address for delivery receiver | C21: 1. Open receiver profile during registration 2. Enable delivery address 3. Submit without address coordinates | D21: System asks for a complete address and location. | E21: Receiver account registration is in progress | F21: Passed | G21: 46235 | H21: QA Team | I21: Passed | J21: 46242 | K21: QA Team | L21: Passed | M21: 46249 | N21: QA Team

Sheet Profile Trust
A2: Feature | B2: Profile Trust | R2: Passed
A3: Test requirement | B3: View/update profile, trust score, availability, and restriction states | R3: Failed
A4: Number of TCs | B4: 10 | R4: Pending
A5: Testing Round | B5: Passed | C5: Failed | D5: Pending | E5: N/A | R5: N/A
A6: Round 1 | B6: =COUNTIF($F$12:$F$1005,B$5) -> 10 | C6: =COUNTIF($F$12:$F$1005,C$5) -> 0 | D6: =COUNTIF($F$12:$F$1005,D$5) -> 0 | E6: =COUNTIF($F$12:$F$1005,E$5) -> 0
A7: Round 2 | B7: =COUNTIF($I$12:$I$1005,B$5) -> 10 | C7: =COUNTIF($I$12:$I$1005,C$5) -> 0 | D7: =COUNTIF($I$12:$I$1005,D$5) -> 0 | E7: =COUNTIF($I$12:$I$1005,E$5) -> 0
A8: Round 3 | B8: =COUNTIF($L$12:$L$1005,B$5) -> 10 | C8: =COUNTIF($L$12:$L$1005,C$5) -> 0 | D8: =COUNTIF($L$12:$L$1005,D$5) -> 0 | E8: =COUNTIF($L$12:$L$1005,E$5) -> 0
A10: Test Case ID | B10: Test Case Description | C10: Test Case Procedure | D10: Expected Results | E10: Pre-conditions | F10: Round 1 | G10: Test date | H10: Tester | I10: Round 2 | J10: Test date | K10: Tester | L10: Round 3 | M10: Test date | N10: Tester | O10: Note
A11: Profile management
A12: TC18 | B12: View current user profile | C12: 1. Sign in 2. Open Profile screen | D12: User information, role, trust score, and verification state are displayed. | E12: User is signed in | F12: Passed | G12: 46235 | H12: QA Team | I12: Passed | J12: 46242 | K12: QA Team | L12: Passed | M12: 46249 | N12: QA Team
A13: TC19 | B13: Update receiver delivery address | C13: 1. Open Profile 2. Edit address 3. Select coordinates 4. Save changes | D13: Updated address and coordinates are saved successfully. | E13: Receiver is signed in | F13: Passed | G13: 46235 | H13: QA Team | I13: Passed | J13: 46242 | K13: QA Team | L13: Passed | M13: 46249 | N13: QA Team
A14: TC20 | B14: Update provider business information | C14: 1. Sign in as provider 2. Open business profile 3. Edit contact fields 4. Save changes | D14: Provider profile displays updated business information. | E14: Provider account exists | F14: Passed | G14: 46235 | H14: QA Team | I14: Passed | J14: 46242 | K14: QA Team | L14: Passed | M14: 46249 | N14: QA Team
A15: Volunteer availability
A16: TC21 | B16: Volunteer toggles availability | C16: 1. Sign in as verified volunteer 2. Open availability control 3. Switch status to available | D16: Volunteer availability is updated and visible to delivery assignment service. | E16: Volunteer is verified | F16: Passed | G16: 46235 | H16: QA Team | I16: Passed | J16: 46242 | K16: QA Team | L16: Passed | M16: 46249 | N16: QA Team
A17: Trust score and account status
A18: TC22 | B18: Restricted user daily reservation limit | C18: 1. Set user trust score to restricted range 2. Create second reservation in same day 3. Submit reservation | D18: System blocks reservation according to restricted daily limit. | E18: User trust score is at or below restriction threshold | F18: Passed | G18: 46235 | H18: QA Team | I18: Passed | J18: 46242 | K18: QA Team | L18: Passed | M18: 46249 | N18: QA Team
A19: TC23 | B19: Banned user token revocation | C19: 1. Set user trust score to banned range 2. Try to refresh token 3. Open protected screen | D19: All refresh tokens are revoked and protected API access is denied. | E19: User status is banned | F19: Passed | G19: 46235 | H19: QA Team | I19: Passed | J19: 46242 | K19: QA Team | L19: Passed | M19: 46249 | N19: QA Team
A20: TC24 | B20: View trust score history | C20: 1. Open Profile 2. Open trust score details | D20: Trust score history displays reason, score change, and timestamp. | E20: User has trust score history records | F20: Passed | G20: 46235 | H20: QA Team | I20: Passed | J20: 46242 | K20: QA Team | L20: Passed | M20: 46249 | N20: QA Team
A21: TC25 | B21: Apply no-show trust penalty | C21: 1. Create confirmed pickup reservation 2. Let QR expire without pickup 3. Run reservation expiry job 4. Open receiver trust history | D21: Reservation becomes no_show, stock is restored, and receiver trust score decreases by 20 points. | E21: Receiver has a confirmed pickup reservation | F21: Passed | G21: 46235 | H21: QA Team | I21: Passed | J21: 46242 | K21: QA Team | L21: Passed | M21: 46249 | N21: QA Team
A22: TC26 | B22: Warn and apply late cancellation penalty | C22: 1. Create confirmed reservation near pickup end time 2. Click Cancel within 30 minutes of pickup end 3. Confirm penalty warning | D22: System shows late-cancel warning, cancels reservation, restores stock, and reduces trust by 10 points. | E22: Reservation is inside late cancellation window | F22: Passed | G22: 46235 | H22: QA Team | I22: Passed | J22: 46242 | K22: QA Team | L22: Passed | M22: 46249 | N22: QA Team
A23: TC27 | B23: Apply food safety violation penalty | C23: 1. Admin records food safety violation for a user/provider 2. Open affected user profile 3. Check trust history and account status | D23: Trust score decreases by 50 points and account restriction/ban threshold is applied if reached. | E23: Food safety violation evidence exists | F23: Passed | G23: 46235 | H23: QA Team | I23: Passed | J23: 46242 | K23: QA Team | L23: Passed | M23: 46249 | N23: QA Team

Sheet Logout
A2: Feature | B2: Logout | R2: Passed
A3: Test requirement | B3: Terminate session and clear local authentication state | R3: Failed
A4: Number of TCs | B4: 1 | R4: Pending
A5: Testing Round | B5: Passed | C5: Failed | D5: Pending | E5: N/A | R5: N/A
A6: Round 1 | B6: =COUNTIF($F$12:$F$1005,B$5) -> 1 | C6: =COUNTIF($F$12:$F$1005,C$5) -> 0 | D6: =COUNTIF($F$12:$F$1005,D$5) -> 0 | E6: =COUNTIF($F$12:$F$1005,E$5) -> 0
A7: Round 2 | B7: =COUNTIF($I$12:$I$1005,B$5) -> 1 | C7: =COUNTIF($I$12:$I$1005,C$5) -> 0 | D7: =COUNTIF($I$12:$I$1005,D$5) -> 0 | E7: =COUNTIF($I$12:$I$1005,E$5) -> 0
A8: Round 3 | B8: =COUNTIF($L$12:$L$1005,B$5) -> 1 | C8: =COUNTIF($L$12:$L$1005,C$5) -> 0 | D8: =COUNTIF($L$12:$L$1005,D$5) -> 0 | E8: =COUNTIF($L$12:$L$1005,E$5) -> 0
A10: Test Case ID | B10: Test Case Description | C10: Test Case Procedure | D10: Expected Results | E10: Pre-conditions | F10: Round 1 | G10: Test date | H10: Tester | I10: Round 2 | J10: Test date | K10: Tester | L10: Round 3 | M10: Test date | N10: Tester | O10: Note
A11: Session termination
A12: TC15 | B12: Logout successfully | C12: 1. Sign in to the app 2. Open account menu 3. Click Logout | D12: Access token is removed, socket disconnects, and user returns to sign-in screen. | E12: User is signed in | F12: Passed | G12: 46235 | H12: QA Team | I12: Passed | J12: 46242 | K12: QA Team | L12: Passed | M12: 46249 | N12: QA Team

Sheet Password
A2: Feature | B2: Password | R2: Passed
A3: Test requirement | B3: Forgot password and reset password validation | R3: Failed
A4: Number of TCs | B4: 2 | R4: Pending
A5: Testing Round | B5: Passed | C5: Failed | D5: Pending | E5: N/A | R5: N/A
A6: Round 1 | B6: =COUNTIF($F$12:$F$1005,B$5) -> 2 | C6: =COUNTIF($F$12:$F$1005,C$5) -> 0 | D6: =COUNTIF($F$12:$F$1005,D$5) -> 0 | E6: =COUNTIF($F$12:$F$1005,E$5) -> 0
A7: Round 2 | B7: =COUNTIF($I$12:$I$1005,B$5) -> 2 | C7: =COUNTIF($I$12:$I$1005,C$5) -> 0 | D7: =COUNTIF($I$12:$I$1005,D$5) -> 0 | E7: =COUNTIF($I$12:$I$1005,E$5) -> 0
A8: Round 3 | B8: =COUNTIF($L$12:$L$1005,B$5) -> 2 | C8: =COUNTIF($L$12:$L$1005,C$5) -> 0 | D8: =COUNTIF($L$12:$L$1005,D$5) -> 0 | E8: =COUNTIF($L$12:$L$1005,E$5) -> 0
A10: Test Case ID | B10: Test Case Description | C10: Test Case Procedure | D10: Expected Results | E10: Pre-conditions | F10: Round 1 | G10: Test date | H10: Tester | I10: Round 2 | J10: Test date | K10: Tester | L10: Round 3 | M10: Test date | N10: Tester | O10: Note
A11: Password recovery
A12: TC16 | B12: Request password reset for registered email | C12: 1. Open Forgot Password 2. Enter registered email 3. Submit request | D12: System sends reset/OTP flow and displays confirmation. | E12: User email exists | F12: Passed | G12: 46235 | H12: QA Team | I12: Passed | J12: 46242 | K12: QA Team | L12: Passed | M12: 46249 | N12: QA Team
A13: TC17 | B13: Reset password with valid OTP | C13: 1. Open reset password screen 2. Enter valid OTP and new password 3. Submit form | D13: Password is updated and old credentials no longer work. | E13: User has a valid OTP | F13: Passed | G13: 46235 | H13: QA Team | I13: Passed | J13: 46242 | K13: QA Team | L13: Passed | M13: 46249 | N13: QA Team

Sheet Login
A2: Feature | B2: Login | R2: Passed
A3: Test requirement | B3: Sign in, token refresh, authorization guard, and role-based access | R3: Failed
A4: Number of TCs | B4: 6 | R4: Pending
A5: Testing Round | B5: Passed | C5: Failed | D5: Pending | E5: N/A | R5: N/A
A6: Round 1 | B6: =COUNTIF($F$12:$F$1005,B$5) -> 6 | C6: =COUNTIF($F$12:$F$1005,C$5) -> 0 | D6: =COUNTIF($F$12:$F$1005,D$5) -> 0 | E6: =COUNTIF($F$12:$F$1005,E$5) -> 0
A7: Round 2 | B7: =COUNTIF($I$12:$I$1005,B$5) -> 6 | C7: =COUNTIF($I$12:$I$1005,C$5) -> 0 | D7: =COUNTIF($I$12:$I$1005,D$5) -> 0 | E7: =COUNTIF($I$12:$I$1005,E$5) -> 0
A8: Round 3 | B8: =COUNTIF($L$12:$L$1005,B$5) -> 6 | C8: =COUNTIF($L$12:$L$1005,C$5) -> 0 | D8: =COUNTIF($L$12:$L$1005,D$5) -> 0 | E8: =COUNTIF($L$12:$L$1005,E$5) -> 0
A10: Test Case ID | B10: Test Case Description | C10: Test Case Procedure | D10: Expected Results | E10: Pre-conditions | F10: Round 1 | G10: Test date | H10: Tester | I10: Round 2 | J10: Test date | K10: Tester | L10: Round 3 | M10: Test date | N10: Tester | O10: Note
A11: Authentication
A12: TC01 | B12: Login with valid receiver account | C12: 1. Open sign-in screen 2. Enter registered receiver email and password 3. Click Sign in | D12: User is authenticated and redirected to the receiver home screen. | E12: Receiver account exists and is active | F12: Passed | G12: 46235 | H12: QA Team | I12: Passed | J12: 46242 | K12: QA Team | L12: Passed | M12: 46249 | N12: QA Team
A13: TC02 | B13: Login with invalid password | C13: 1. Open sign-in screen 2. Enter registered email and wrong password 3. Click Sign in | D13: System rejects login and displays an invalid credential message. | E13: User account exists | F13: Passed | G13: 46235 | H13: QA Team | I13: Passed | J13: 46242 | K13: QA Team | L13: Passed | M13: 46249 | N13: QA Team
A14: TC03 | B14: Login with banned account | C14: 1. Open sign-in screen 2. Enter banned account credentials 3. Click Sign in | D14: System blocks login and shows account status message. | E14: Account status is banned | F14: Passed | G14: 46235 | H14: QA Team | I14: Passed | J14: 46242 | K14: QA Team | L14: Passed | M14: 46249 | N14: QA Team
A15: Token refresh
A16: TC04 | B16: Refresh access token | C16: 1. Sign in successfully 2. Wait until access token is near expiry 3. Call an authenticated API | D16: Client refreshes token and continues the request without forcing logout. | E16: Refresh token is valid | F16: Passed | G16: 46235 | H16: QA Team | I16: Passed | J16: 46242 | K16: QA Team | L16: Passed | M16: 46249 | N16: QA Team
A17: TC05 | B17: Reject expired refresh token | C17: 1. Sign in successfully 2. Invalidate refresh token 3. Call an authenticated API after access token expiry | D17: System clears session and redirects user to sign in. | E17: Refresh token is expired or revoked | F17: Passed | G17: 46235 | H17: QA Team | I17: Passed | J17: 46242 | K17: QA Team | L17: Passed | M17: 46249 | N17: QA Team
A18: Role-based access
A19: TC06 | B19: Role guard blocks unauthorized route | C19: 1. Sign in as receiver 2. Open provider-only listing management API | D19: API returns forbidden response and no provider data is exposed. | E19: Receiver account is active | F19: Passed | G19: 46235 | H19: QA Team | I19: Passed | J19: 46242 | K19: QA Team | L19: Passed | M19: 46249 | N19: QA Team

Sheet Admin Controls
A2: Feature | B2: Admin Controls
A3: Test requirement | B3: Admin KYC review, campaign approval, user governance, violation handling, and operational monitoring
A4: Number of TCs | B4: 8
A5: Testing Round | B5: Passed | C5: Failed | D5: Pending | E5: N/A
A6: Round 1 | B6: =COUNTIF($F$12:$F$1005,B$5) -> 8 | C6: =COUNTIF($F$12:$F$1005,C$5) -> 0 | D6: =COUNTIF($F$12:$F$1005,D$5) -> 0 | E6: =COUNTIF($F$12:$F$1005,E$5) -> 0
A7: Round 2 | B7: =COUNTIF($I$12:$I$1005,B$5) -> 8 | C7: =COUNTIF($I$12:$I$1005,C$5) -> 0 | D7: =COUNTIF($I$12:$I$1005,D$5) -> 0 | E7: =COUNTIF($I$12:$I$1005,E$5) -> 0
A8: Round 3 | B8: =COUNTIF($L$12:$L$1005,B$5) -> 8 | C8: =COUNTIF($L$12:$L$1005,C$5) -> 0 | D8: =COUNTIF($L$12:$L$1005,D$5) -> 0 | E8: =COUNTIF($L$12:$L$1005,E$5) -> 0
A10: Test Case ID | B10: Test Case Description | C10: Test Case Procedure | D10: Expected Results | E10: Pre-conditions | F10: Round 1 | G10: Test date | H10: Tester | I10: Round 2 | J10: Test date | K10: Tester | L10: Round 3 | M10: Test date | N10: Tester | O10: Note
A11: KYC review
A12: TC28 | B12: Admin reviews pending provider KYC | C12: 1. Sign in as admin 2. Open /admin/providers 3. Open pending provider detail 4. Review selfie, ID document, and business information | D12: Admin can view all submitted verification evidence and provider profile details. | E12: New provider account is pending verification | F12: Passed | G12: 46235 | H12: QA Team | I12: Passed | J12: 46242 | K12: QA Team | L12: Passed | M12: 46249 | N12: QA Team
A13: TC29 | B13: Admin approves provider profile | C13: 1. Open pending provider detail 2. Click Approve 3. Confirm approval | D13: Provider status becomes active and provider can create food listings. | E13: Provider KYC information is valid | F13: Passed | G13: 46235 | H13: QA Team | I13: Passed | J13: 46242 | K13: QA Team | L13: Passed | M13: 46249 | N13: QA Team
A14: TC30 | B14: Admin rejects incomplete provider profile | C14: 1. Open pending provider detail 2. Click Reject 3. Enter rejection reason 4. Confirm rejection | D14: Provider status is rejected and provider receives notification to correct missing information. | E14: Provider KYC information is incomplete or invalid | F14: Passed | G14: 46235 | H14: QA Team | I14: Passed | J14: 46242 | K14: QA Team | L14: Passed | M14: 46249 | N14: QA Team
A15: User governance
A16: TC31 | B16: Admin views and filters user list | C16: 1. Sign in as admin 2. Open /admin/users 3. Filter by role or trust score 4. Open a user detail | D16: User list filters correctly and selected user detail displays role, status, and trust score. | E16: Users exist across multiple roles | F16: Passed | G16: 46235 | H16: QA Team | I16: Passed | J16: 46242 | K16: QA Team | L16: Passed | M16: 46249 | N16: QA Team
A17: TC32 | B17: Admin bans user and revokes tokens | C17: 1. Open user detail 2. Click Ban user 3. Confirm ban action 4. Try refreshing token from banned account | D17: User status becomes banned and all refresh tokens are revoked. | E17: User account exists and is eligible for moderation | F17: Passed | G17: 46235 | H17: QA Team | I17: Passed | J17: 46242 | K17: QA Team | L17: Passed | M17: 46249 | N17: QA Team
A18: Operational monitoring
A19: TC33 | B19: Admin monitors delivery status | C19: 1. Create a delivery reservation 2. Sign in as admin 3. Open /admin/deliveries 4. Find the new delivery | D19: Admin sees current delivery status, assigned shipper, and lifecycle progress. | E19: Delivery exists in assigned or in-progress status | F19: Passed | G19: 46235 | H19: QA Team | I19: Passed | J19: 46242 | K19: QA Team | L19: Passed | M19: 46249 | N19: QA Team
A20: TC34 | B20: Admin monitors bulk run progress | C20: 1. Create and approve a bulk run 2. Sign in as admin 3. Open /admin/bulk-runs 4. Review served portions and distribution stops | D20: Admin sees bulk run status, requested quantity, served quantity, and distribution progress. | E20: Bulk run exists with at least one distribution stop | F20: Passed | G20: 46235 | H20: QA Team | I20: Passed | J20: 46242 | K20: QA Team | L20: Passed | M20: 46249 | N20: QA Team
A21: Violation handling
A22: TC35 | B22: Admin processes violation report | C22: 1. Submit a report against user/listing/delivery/campaign 2. Sign in as admin 3. Open report management 4. Review evidence and resolve action | D22: Report status updates and related user/listing/trust action is applied according to admin decision. | E22: Violation report exists | F22: Passed | G22: 46235 | H22: QA Team | I22: Passed | J22: 46242 | K22: QA Team | L22: Passed | M22: 46249 | N22: QA Team

Sheet Campaign Kitchen Ops
A2: Feature | B2: Campaign Kitchen Ops
A3: Test requirement | B3: Campaign creation, volunteer staffing, kitchen preparation, meal distribution, handoff QR, and campaign transport
A4: Number of TCs | B4: 28
A5: Testing Round | B5: Passed | C5: Failed | D5: Pending | E5: N/A
A6: Round 1 | B6: =COUNTIF($F$12:$F$1005,B$5) -> 28 | C6: =COUNTIF($F$12:$F$1005,C$5) -> 0 | D6: =COUNTIF($F$12:$F$1005,D$5) -> 0 | E6: =COUNTIF($F$12:$F$1005,E$5) -> 0
A7: Round 2 | B7: =COUNTIF($I$12:$I$1005,B$5) -> 28 | C7: =COUNTIF($I$12:$I$1005,C$5) -> 0 | D7: =COUNTIF($I$12:$I$1005,D$5) -> 0 | E7: =COUNTIF($I$12:$I$1005,E$5) -> 0
A8: Round 3 | B8: =COUNTIF($L$12:$L$1005,B$5) -> 28 | C8: =COUNTIF($L$12:$L$1005,C$5) -> 0 | D8: =COUNTIF($L$12:$L$1005,D$5) -> 0 | E8: =COUNTIF($L$12:$L$1005,E$5) -> 0
A10: Test Case ID | B10: Test Case Description | C10: Test Case Procedure | D10: Expected Results | E10: Pre-conditions | F10: Round 1 | G10: Test date | H10: Tester | I10: Round 2 | J10: Test date | K10: Tester | L10: Round 3 | M10: Test date | N10: Tester | O10: Note
A11: Campaign lifecycle
A12: TC71 | B12: Create charity kitchen campaign | C12: 1. Sign in as charity organization 2. Open campaign creation form 3. Enter title, kitchen address, schedule, target servings, menu, and shifts 4. Submit campaign | D12: Campaign is created with planned menu items, shifts, kitchen location, and scheduled status. | E12: Charity organization account is active | F12: Passed | G12: 46235 | H12: QA Team | I12: Passed | J12: 46242 | K12: QA Team | L12: Passed | M12: 46249 | N12: QA Team
A13: TC72 | B13: Reject invalid campaign schedule | C13: 1. Open campaign creation form 2. Enter end time before start time or date outside allowed range 3. Submit campaign | D13: System rejects the campaign and displays schedule validation message. | E13: Charity organization is signed in | F13: Passed | G13: 46235 | H13: QA Team | I13: Passed | J13: 46242 | K13: QA Team | L13: Passed | M13: 46249 | N13: QA Team
A14: TC73 | B14: Admin approves pending campaign | C14: 1. Charity submits a new campaign 2. Sign in as admin 3. Open /admin/campaigns 4. Review campaign detail and click Approve | D14: Campaign status changes from pending_approval to active and becomes visible for volunteer registration. | E14: Campaign is pending admin approval | F14: Passed | G14: 46235 | H14: QA Team | I14: Passed | J14: 46242 | K14: QA Team | L14: Passed | M14: 46249 | N14: QA Team
A15: TC74 | B15: Admin rejects campaign and charity revises | C15: 1. Charity submits an incomplete campaign 2. Admin rejects with reason 3. Charity opens campaign form 4. Update missing information and resubmit | D15: Campaign returns to charity for revision, then can be resubmitted for admin approval. | E15: Campaign information is incomplete | F15: Passed | G15: 46235 | H15: QA Team | I15: Passed | J15: 46242 | K15: QA Team | L15: Passed | M15: 46249 | N15: QA Team
A16: TC78 | B16: Start campaign within allowed start window | C16: 1. Open campaign manage page 2. Click Start Campaign near scheduled start time 3. Confirm action | D16: Campaign status changes to in_progress and kitchen task workflow becomes available. | E16: Campaign is scheduled and current time is inside start window | F16: Passed | G16: 46235 | H16: QA Team | I16: Passed | J16: 46242 | K16: QA Team | L16: Passed | M16: 46249 | N16: QA Team
A17: TC87 | B17: Charity cancels open campaign | C17: 1. Sign in as charity organization 2. Open owned open campaign 3. Click Cancel Campaign 4. Confirm cancellation | D17: Campaign status changes to cancelled and it is no longer available for new volunteer registration. | E17: Campaign is open and owned by the charity | F17: Passed | G17: 46235 | H17: QA Team | I17: Passed | J17: 46242 | K17: QA Team | L17: Passed | M17: 46249 | N17: QA Team
A18: TC88 | B18: Complete campaign with actual servings | C18: 1. Sign in as charity organization 2. Open in-progress campaign manage page 3. Click Complete Campaign 4. Enter actual servings and completion note 5. Confirm completion | D18: Campaign status changes to completed and final served/actual serving totals are saved. | E18: Campaign is in_progress | F18: Passed | G18: 46235 | H18: QA Team | I18: Passed | J18: 46242 | K18: QA Team | L18: Passed | M18: 46249 | N18: QA Team
A19: TC89 | B19: Reject early campaign completion without reason | C19: 1. Open in-progress campaign before scheduled end 2. Click Complete Campaign 3. Leave early-end reason empty 4. Submit completion | D19: System rejects early completion and asks for confirmation reason. | E19: Campaign has not reached scheduled end time | F19: Passed | G19: 46235 | H19: QA Team | I19: Passed | J19: 46242 | K19: QA Team | L19: Passed | M19: 46249 | N19: QA Team
A20: TC90 | B20: Submit campaign change request | C20: 1. Sign in as charity organization 2. Open existing campaign 3. Edit schedule, kitchen address, or expected servings 4. Submit change request | D20: Change request is created with pending status and original campaign data remains active until approval. | E20: Campaign exists and no other change request is pending | F20: Passed | G20: 46235 | H20: QA Team | I20: Passed | J20: 46242 | K20: QA Team | L20: Passed | M20: 46249 | N20: QA Team
A21: TC91 | B21: Cancel pending campaign change request | C21: 1. Open campaign change request history 2. Select pending change request 3. Click Cancel Request | D21: Change request status changes to cancelled and no campaign field is updated. | E21: Campaign has a pending change request submitted by the charity | F21: Passed | G21: 46235 | H21: QA Team | I21: Passed | J21: 46242 | K21: QA Team | L21: Passed | M21: 46249 | N21: QA Team
A22: Volunteer staffing
A23: TC75 | B23: Volunteer applies to campaign shift | C23: 1. Sign in as verified volunteer 2. Open public campaign detail 3. Select an available shift and role 4. Submit application | D23: Volunteer application is created as pending for the selected shift. | E23: Campaign has open shift slots | F23: Passed | G23: 46235 | H23: QA Team | I23: Passed | J23: 46242 | K23: QA Team | L23: Passed | M23: 46249 | N23: QA Team
A24: TC76 | B24: Reject duplicate or conflicting shift application | C24: 1. Apply to one campaign shift 2. Try to apply again or select an overlapping shift 3. Submit application | D24: System blocks duplicate/conflicting application and keeps existing assignment unchanged. | E24: Volunteer already has a pending or assigned campaign shift | F24: Passed | G24: 46235 | H24: QA Team | I24: Passed | J24: 46242 | K24: QA Team | L24: Passed | M24: 46249 | N24: QA Team
A25: TC77 | B25: Charity reviews volunteer assignment | C25: 1. Sign in as charity organization 2. Open campaign manage detail 3. Review pending volunteer 4. Approve or reject the application | D25: Assignment status is updated and shift filled count changes when approved. | E25: Campaign has pending volunteer applications | F25: Passed | G25: 46235 | H25: QA Team | I25: Passed | J25: 46242 | K25: QA Team | L25: Passed | M25: 46249 | N25: QA Team
A26: TC92 | B26: Manage campaign shifts | C26: 1. Open campaign schedule management 2. Add a new shift 3. Edit shift time or slot count 4. Delete an unused shift | D26: Shift list is updated and schedule reflects add/edit/delete actions. | E26: Campaign is owned by charity and selected shift has no registered volunteer when deleting | F26: Passed | G26: 46235 | H26: QA Team | I26: Passed | J26: 46242 | K26: QA Team | L26: Passed | M26: 46249 | N26: QA Team
A27: TC93 | B27: Reject deleting shift with registered volunteer | C27: 1. Open campaign schedule management 2. Select shift with pending or assigned volunteer 3. Click Delete Shift | D27: System blocks deletion and keeps the shift unchanged. | E27: Shift already has volunteer registration or assignment | F27: Passed | G27: 46235 | H27: QA Team | I27: Passed | J27: 46242 | K27: QA Team | L27: Passed | M27: 46249 | N27: QA Team
A28: Kitchen preparation
A29: TC79 | B29: Record kitchen safety log | C29: 1. Sign in as assigned chef 2. Open kitchen ops panel 3. Enter safety check result and optional proof photo 4. Submit log | D29: Safety log is saved and visible in campaign kitchen activity. | E29: Chef is assigned or checked in for the campaign | F29: Passed | G29: 46235 | H29: QA Team | I29: Passed | J29: 46242 | K29: QA Team | L29: Passed | M29: 46249 | N29: QA Team
A30: TC80 | B30: Complete dish preparation step | C30: 1. Open assigned kitchen task 2. Select the next dish step 3. Mark step completed with proof when required | D30: Dish step status is updated and next step becomes available according to order. | E30: Campaign is in_progress and menu items have generated dish steps | F30: Passed | G30: 46235 | H30: QA Team | I30: Passed | J30: 46242 | K30: QA Team | L30: Passed | M30: 46249 | N30: QA Team
